Workbook

Sheet Summary
A1: NAME : MUHAMMED FAIZ
A2: PATIENT SUMMARY: NOV 2025 - OCT 2026
A3: Sl No | B3: Month | C3: Total Patients | D3: Total Bill Amount
A4: 1 | B4: November 2025 | C4: ='Nov-2025'!E10 | D4: ='Nov-2025'!F11
A5: 2 | B5: December 2025 | C5: ='Dec-2025'!E97 | D5: ='Dec-2025'!F98
A6: 3 | B6: January 2026 | C6: ='Jan-2026'!E57 | D6: ='Jan-2026'!F58
A7: 4 | B7: February 2026 | C7: ='Feb-2026'!E140 | D7: ='Feb-2026'!F141
A8: 5 | B8: March 2026 | C8: ='Mar-2026'!E65 | D8: ='Mar-2026'!F66
A9: 6 | B9: April 2026 | C9: ='Apr-2026'!E68 | D9: ='Apr-2026'!F69
A10: 7 | B10: May 2026 | C10: ='May-2026'!E57 | D10: ='May-2026'!F58
A11: 8 | B11: June 2026 | C11: ='Jun-2026'!E58 | D11: ='Jun-2026'!F59
A12: 9 | B12: July 2026 | C12: ='Jul-2026'!E25 | D12: ='Jul-2026'!F26
A13: 10 | B13: August 2026 | C13: ='Aug-2026'!E95 | D13: ='Aug-2026'!F96
A14: 11 | B14: September 2026 | C14: ='Sep-2026'!E45 | D14: ='Sep-2026'!F46
A15: 12 | B15: October 2026 | C15: ='Oct-2026'!E27 | D15: ='Oct-2026'!F28
A17: GRAND TOTAL PATIENTS | C17: =SUM(C4:C15) | D17: =SUM(D4:D15)
A19: Note: Nov 2025 - Jun 2026 from the MAIN OG 2 workbook; Jul 2026 has no data yet (blank template); Aug & Sep from the monthly files; Oct from the screenshot (rows 1-22).

Sheet Nov-2025
A1: NAME : MUHAMMED FAIZ
A2: PATIENT DATA OF NOVEMBER 2025
A3: Sl No | B3: Date | C3: File Number | D3: Patient Name | E3: Consultation / Service / Department | F3: Bill Amount
A4: 1 | B4: 27 Nov 2025 | C4: 124285 | D4: Reebu Nazal | E4: GP, Orthopedic
A5: 2 | B5: 27 Nov 2025 | C5: 124286 | D5: Shanid | E5: GP, Orthopedic
A6: 3 | B6: 27 Nov 2025 | C6: 124287 | D6: Kunheedutty | E6: GP, Orthopedic
A7: 4 | B7: 27 Nov 2025 | C7: 124274 | D7: Poozi Kunnath | E7: Internal Medicine, Ophthalmology, Lab, Ophthalmology Services
A8: 5 | B8: 27 Nov 2025 | C8: 124275 | D8: Ayisha Abdurahman | E8: Internal Medicine, Ophthalmology, Lab, Ophthalmology Services
A10: TOTAL PATIENTS OF NOVEMBER 2025 | E10: =COUNTA(B4:B8)
A11: TOTAL BILL AMOUNT OF NOVEMBER 2025 | F11: =SUM(F4:F8)

Sheet Dec-2025
A1: NAME : MUHAMMED FAIZ
A2: PATIENT DATA OF DECEMBER 2025
A3: Sl No | B3: Date | C3: File Number | D3: Patient Name | E3: Consultation / Service / Department | F3: Bill Amount
A4: 1 | B4: 01 Dec 2025 | C4: 124469 | D4: Sumisha Habeeb | E4: GP, Internal Medicine, Lab, Radiology
A5: 2 | B5: 01 Dec 2025 | C5: 124467 | D5: Zareen Nihas | E5: GP, Ophthalmology, Lab, Ophthalmology Services
A6: 3 | B6: 01 Dec 2025 | C6: 124468 | D6: Nihas | E6: GP, Internal Medicine, Lab, Radiology
A7: 4 | B7: 04 Dec 2025 | C7: 124469 | D7: Sumisha Habeeb | E7: Internal Medicine, Lab, Radiology
A8: 5 | B8: 04 Dec 2025 | C8: 124467 | D8: Zareen Nihas | E8: Ophthalmology, Follow-up
A9: 6 | B9: 06 Dec 2025 | C9: 124707 | D9: Sanal Kadavingal | E9: GP, Cardiology, Lab, Cardiology Services
A10: 7 | B10: 06 Dec 2025 | C10: 124713 | D10: Ahmed Ibrahim | E10: GP, Cardiology, Gastroenterology, Lab, Cardiology Services
A11: 8 | B11: 07 Dec 2025 | C11: 124713 | D11: Ahmed Ibrahim | E11: Cardiology, Gastroenterology, Lab, Cardiology Services
A12: 9 | B12: 07 Dec 2025 | C12: 124766 | D12: Arif Sher | E12: GP, Cardiology, Lab
A13: 10 | B13: 07 Dec 2025 | C13: 124771 | D13: Kishan Lal | E13: GP, Ophthalmology, Ophthalmology Services
A14: 11 | B14: 07 Dec 2025 | C14: 124784 | D14: Anwara Begum | E14: GP, Family Medicine, Lab
A15: 12 | B15: 07 Dec 2025 | C15: 124787 | D15: Issiahaka Maazou | E15: GP, General Surgery, Lab, Radiology
... A95: 92 | B95: 31 Dec 2025 | C95: 125894 | D95: Muhammed Umar | E95: GP, Orthopedic, Internal Medicine, Radiology, MRI, USG, Lab
A97: TOTAL PATIENTS OF DECEMBER 2025 | E97: =COUNTA(B4:B95)
A98: TOTAL BILL AMOUNT OF DECEMBER 2025 | F98: =SUM(F4:F95)

Sheet Jan-2026
A1: NAME : MUHAMMED FAIZ
A2: PATIENT DATA OF JANUARY 2026
A3: Sl No | B3: Date | C3: File Number | D3: Patient Name | E3: Consultation / Service / Department | F3: Bill Amount
A4: 1 | B4: 01 Jan 2026 | C4: 125848 | D4: Mohammed Shahab | E4: GP Follow-up, Lab
A5: 2 | B5: 06 Jan 2026 | C5: TMC132373 | D5: Muhammed Majid
A6: 3 | B6: 07 Jan 2026 | C6: 126214 | D6: Varalakshmi Undru | E6: GP, Neurology, X-Ray, NCS
A7: 4 | B7: 07 Jan 2026 | C7: 126216 | D7: Mohammed Mijanur | E7: GP, Orthopedic, Injection, MRI
A8: 5 | B8: 07 Jan 2026 | C8: 126192 | D8: Muhammed Jaseel | E8: Orthopedic, Lab, X-Ray, MRI
A9: 6 | B9: 07 Jan 2026 | C9: 126194 | D9: Anas Abdul Vahid | E9: Orthopedic, X-Ray, MRI
A10: 7 | B10: 07 Jan 2026 | C10: 126197 | D10: Mubeen | E10: Orthopedic, X-Ray, MRI
A11: 8 | B11: 07 Jan 2026 | C11: 126200 | D11: Mohammed Musthafa | E11: Orthopedic, X-Ray, MRI
A12: 9 | B12: 07 Jan 2026 | C12: 126201 | D12: Shejeer | E12: Orthopedic, X-Ray, MRI
A13: 10 | B13: 07 Jan 2026 | C13: 126182 | D13: Imran Akthar | E13: Orthopedic, Lab, X-Ray, MRI
A14: 11 | B14: 07 Jan 2026 | C14: 126183 | D14: Waqar Ali | E14: Orthopedic, Lab, X-Ray, MRI
A15: 12 | B15: 07 Jan 2026 | C15: 126191 | D15: Muhammed Shaheer | E15: GP, Orthopedic, USG, MRI
A16: 13 | B16: 08 Jan 2026 | C16: 126209 | D16: Dilip Kumar | E16: GP, Dermatology, Ophthalmology, Ophthalmology Services
A17: 14 | B17: 08 Jan 2026 | C17: 126214 | D17: Varalakshmi Undru | E17: Neurology Follow-up
... A45: 42 | B45: 23 Jan 2026 | C45: TMC127021 | D45: Sayed Karim | E45: Dr Mustafa, Dr Higazy Mohamed, Radiology
A46: 43 | B46: 24 Jan 2026 | C46: 123454 | D46: Raseena
A47: 44 | B47: 24 Jan 2026 | C47: 126802 | D47: Muneer
A48: 45 | B48: 24 Jan 2026 | C48: 126683 | D48: Rizwan Saeed
A49: 46 | B49: 24 Jan 2026 | C49: TMC12709 | D49: Ahmed Mohammed | E49: Dr Yassin
A50: 47 | B50: 26 Jan 2026 | C50: 126683 | D50: Rizwan Saeed
A51: 48 | B51: 26 Jan 2026 | C51: 126819 | D51: Ankar Mia
A52: 49 | B52: 28 Jan 2026 | C52: 126197 | D52: Mubeen
A53: 50 | B53: 29 Jan 2026 | C53: TMC127390 | D53: Dancel Gen | E53: Dr Mustafa, Dr Ihab, Radiology, USG
A54: 51 | B54: 30 Jan 2026 | C54: TMC127390 | D54: Dancel Gen | E54: Dr Ihab
A55: 52 | B55: 31 Jan 2026 | C55: 126683 | D55: Rizwan Saeed
A57: TOTAL PATIENTS OF JANUARY 2026 | E57: =COUNTA(B4:B55)
A58: TOTAL BILL AMOUNT OF JANUARY 2026 | F58: =SUM(F4:F55)

Sheet Feb-2026
A1: NAME : MUHAMMED FAIZ
A2: PATIENT DATA OF FEBRUARY 2026
A3: Sl No | B3: Date | C3: File Number | D3: Patient Name | E3: Consultation / Service / Department | F3: Bill Amount
A4: 1 | B4: 01 Feb 2026 | C4: 125964 | D4: Khadeeja Zubair | E4: Pediatric, Lab, Injection
A5: 2 | B5: 01 Feb 2026 | C5: TMC054178 | D5: Maha Ahmed | E5: Dr Montasir, Injection
A6: 3 | B6: 01 Feb 2026 | C6: TMC127021 | D6: Syed | E6: Dr Ihab
A7: 4 | B7: 02 Feb 2026 | C7: TMC035577 | D7: Shiv Kumar | E7: Dr Afaf, Dr Agnel, Lab, Radiology, Injection, Physio
A8: 5 | B8: 02 Feb 2026 | C8: TMC127561 | D8: Abdul Akthar | E8: Dr Afaf, Dr Agnel, Radiology, Injection
A9: 6 | B9: 02 Feb 2026 | C9: TMC127530 | D9: Thazin Thaw | E9: Dr Afsheen, Dr Nandi
A10: 7 | B10: 02 Feb 2026 | C10: TMC127528 | D10: Ahmed Mohamed | E10: Dr Mofeed, Dr Nandi, ENT Services
A11: 8 | B11: 02 Feb 2026 | C11: TMC127534 | D11: Mohamed Nasreldin | E11: Dr Mofeed, Dr Nandi, Lab
A12: 9 | B12: 02 Feb 2026 | C12: TMC127536 | D12: Hasan Moustafa H | E12: Dr Mofeed, Dr Nandi, Lab
A13: 10 | B13: 03 Feb 2026 | C13: TMC127616 | D13: Suleman Ahmed M | E13: Dr Afaf, Dr Agnel, Radiology, Physio
A14: 11 | B14: 03 Feb 2026 | C14: TMC127620 | D14: Khalifa Abdullah | E14: Dr Enas, Lab
A15: 12 | B15: 03 Feb 2026 | C15: TMC035577 | D15: Shiva Kumar | E15: Physio
... A29: 26 | B29: 07 Feb 2026 | C29: TMC127767 | D29: Said Mohammed | E29: Dr Nandi
A30: 27 | B30: 07 Feb 2026 | C30: TMC054178 | E30: Family Medicine, Injection
A31: 28 | B31: 07 Feb 2026 | C31: TMC035577 | D31: Shiva Kumar | E31: Physio
A32: 29 | B32: 08 Feb 2026 | C32: TMC083646 | D32: Muhammad Hanan F | E32: Dr Afsheen, Dr Agnel, Radiology
A33: 30 | B33: 08 Feb 2026 | C33: TMC127829 | D33: Aman Shah | E33: Dr Afsheen, Dr Agnel, Radiology
A34: 31 | B34: 08 Feb 2026 | C34: TMC112215 | E34: Gynecology Follow-up, Lab
A35: 32 | B35: 08 Feb 2026 | C35: TMC035577 | D35: Shiva Kumar | E35: Physio
A36: 33 | B36: 09 Feb 2026 | C36: TMC127864 | D36: Yaqob Jana | E36: Dr Afsheen, Dr Agnel, Physio
A37: 34 | B37: 09 Feb 2026 | C37: TMC127868 | D37: Mohammed Shahada | E37: Dr Afsheen, Lab
A38: 35 | B38: 09 Feb 2026 | C38: TMC127880 | D38: Muhammad Shahza | E38: Dr Afsheen, Dr Feras, Dr Ali
A39: 36 | B39: 09 Feb 2026 | C39: TMC086982 | D39: Sunitha Singh | E39: Dr Montasir
A40: 37 | B40: 09 Feb 2026 | C40: TMC127848 | D40: Jaesan Mariano | E40: Dr Mofeed, Dr Agnel, Radiology
A41: 38 | B41: 09 Feb 2026 | C41: TMC054178 | E41: Injection
A42: 39 | B42: 09 Feb 2026 | C42: TMC044998 | E42: Family Medicine, Lab, Injection
A43: 40 | B43: 09 Feb 2026 | C43: TMC126338 | E43: Family Medicine
A44: 41 | B44: 09 Feb 2026 | C44: TMC031248 | E44: Family Medicine
A45: 42 | B45: 09 Feb 2026 | C45: TMC015474 | E45: Family Medicine, Orthopedic, X-Ray
A46: 43 | B46: 10 Feb 2026 | C46: TMC127941 | D46: Mohamed Awad Ahm | E46: Dr Afsheen, Dr Nandi, Injection
A47: 44 | B47: 10 Feb 2026 | C47: TMC127938 | D47: Md Sourov | E47: Dr Afsheen, Dr Ali, Dr Ferous, Lab, Injection, USG
A48: 45 | B48: 10 Feb 2026 | C48: TMC127937 | D48: Gamal Uddin | E48: Dr Afsheen, Dr Agnel, Radiology, Lab
A49: 46 | B49: 10 Feb 2026 | C49: TMC127919 | D49: Kutub Uddin | E49: Dr Afsheen, Dr Agnel, Lab, Radiology
A50: 47 | B50: 10 Feb 2026 | C50: TMC127928 | D50: Nezam Pasha | E50: Dr Afsheen, Dr Droos, Ophthalmology Services
A51: 48 | B51: 10 Feb 2026 | C51: TMC127900 | D51: Niyas Karimbanchol | E51: Dr Ihab
A52: 49 | B52: 10 Feb 2026 | C52: TMC070809 | D52: Mahamood Vazhaval | E52: Dr Afsheen, Dr Nandi
A53: 50 | B53: 10 Feb 2026 | C53: TMC112557 | D53: Mehrunnisa Moha | E53: Dr Night, Injection
...

Sheet Mar-2026
A1: NAME : MUHAMMED FAIZ
A2: PATIENT DATA OF MARCH 2026
A3: Sl No | B3: Date | C3: File Number | D3: Patient Name | E3: Consultation / Service / Department | F3: Bill Amount
A4: 1 | B4: 01 Mar 2026 | C4: TMC128855 | D4: Mohammed Omar | E4: Dr Said, Radiology
A5: 2 | B5: 01 Mar 2026 | C5: TMC127616 | D5: Sulaiman | E5: Physio
A6: 3 | B6: 02 Mar 2026 | C6: TMC127848 | D6: Jeason | E6: Dr Agnel
A7: 4 | B7: 02 Mar 2026 | C7: TMC128610 | D7: Sufina Harees | E7: ENT Follow-up, Lab, ENT Services
A8: 5 | B8: 03 Mar 2026 | C8: TMC128925 | D8: Azizullah Khudainaz | E8: Dr Roaa, Dr Nandi, Radiology, Lab, ENT Services
A9: 6 | B9: 03 Mar 2026 | C9: TMC128855 | D9: Omar | E9: General Surgery
A10: 7 | B10: 03 Mar 2026 | C10: TMC127616 | D10: Sulaiman | E10: Physio
A11: 8 | B11: 04 Mar 2026 | C11: TMC128955 | D11: Niazieh Halloum | E11: Dr Agnel, Lab, Radiology
A12: 9 | B12: 04 Mar 2026 | C12: TMC035577 | D12: Shiva Kumar | E12: GP, Orthopedic, Physio
A13: 10 | B13: 05 Mar 2026 | C13: TMC128990 | D13: Yasmin Helali | E13: Dr Agnel
A14: 11 | B14: 05 Mar 2026 | C14: TMC129000 | D14: Abdulla Mohammed | E14: Dr Nandi
A15: 12 | B15: 05 Mar 2026 | C15: TMC054178 | E15: Gynecology
A16: 13 | B16: 05 Mar 2026 | C16: TMC128855 | D16: Omar | E16: General Surgery Follow-up
A17: 14 | B17: 06 Mar 2026 | C17: TMC129013 | D17: Daeni Daiman | E17: Dr Roaa, Dr Nandi
A18: 15 | B18: 06 Mar 2026 | C18: TMC129015 | D18: Jana Mahmed | E18: Dr Afsheen, Dr Nandi, Lab
A19: 16 | B19: 06 Mar 2026 | C19: TMC129012 | D19: R Shakil Khan | E19: Dr Afsheen, Dr Droos, Ophthalmology Services
A20: 17 | B20: 07 Mar 2026 | C20: TMC129037 | D20: Birtukan Woldemar | E20: Dr Nandi
A21: 18 | B21: 07 Mar 2026 | C21: TMC129039 | D21: Huda Mehwish | E21: Dr Roaa, Dr Nandi, ENT Services
A22: 19 | B22: 07 Mar 2026 | C22: TMC129012 | D22: Shakil Khan | E22: Ophthalmology
A23: 20 | B23: 07 Mar 2026 | C23: TMC128855 | D23: Omar | E23: Allergy Medicine
A24: 21 | B24: 07 Mar 2026 | C24: TMC035577 | D24: Shiva Kumar | E24: Physio
A25: 22 | B25: 09 Mar 2026 | C25: TMC129088 | D25: Fakhira Saleh | E25: Dr Gawher
A26: 23 | B26: 09 Mar 2026 | C26: TMC129082 | D26: Mohammad Adnan | E26: Dr Nandi, ENT Services
A27: 24 | B27: 09 Mar 2026 | C27: TMC129085 | D27: Maria Lorenel | E27: Dr Nandi, ENT Services
... A32: 29 | B32: 10 Mar 2026 | C32: TMC129130 | D32: Ibrahim Kolib S | E32: Dr Asma, Dr Nandi, Dr Ali Droos, Radiology, ENT Services, Ophthalmology Services
A33: 30 | B33: 10 Mar 2026 | C33: TMC015474 | E33: Cardiology, ECG
A34: 31 | B34: 12 Mar 2026 | C34: TMC013889 | D34: Muhammad Ashraf | E34: Dr Afsheen, Dr Ihab, Radiology
A35: 32 | B35: 12 Mar 2026 | C35: TMC128855 | D35: Omar | E35: Internal Medicine, General Surgery Follow-up
A36: 33 | B36: 12 Mar 2026 | C36: TMC035577 | D36: Shiva Kumar | E36: Physio
A37: 34 | B37: 12 Mar 2026 | C37: TMC128214 | D37: Shamma | E37: Gastroenterology, Lab, USG
A38: 35 | B38: 13 Mar 2026 | C38: TMC128214 | D38: Shamma | E38: Gastroenterology Follow-up
A39: 36 | B39: 14 Mar 2026 | C39: TMC129268 | D39: Shirin Saleem | E39: Dr Ghassan, USG
A40: 37 | B40: 14 Mar 2026 | C40: TMC129012 | D40: Shakil Khan | E40: Ophthalmology
A41: 38 | B41: 14 Mar 2026 | C41: TMC128214 | D41: Shamma | E41: Gastroenterology
A42: 39 | B42: 14 Mar 2026 | C42: TMC125736 | D42: Hiba | E42: GP, Gynecology, Lab, USG
A43: 40 | B43: 15 Mar 2026 | C43: TMC035577 | D43: Shiva Kumar | E43: Physio
A44: 41 | B44: 16 Mar 2026 | C44: TMC129000 | D44: Abdulla Mohammed | E44: ENT
...

Sheet Apr-2026
A1: NAME : MUHAMMED FAIZ
A2: PATIENT DATA OF APRIL 2026
A3: Sl No | B3: Date | C3: File Number | D3: Patient Name | E3: Consultation / Service / Department | F3: Bill Amount
A4: 1 | B4: 01 Apr 2026 | C4: TMC129798 | D4: Abdul Halim | E4: Dr Mustafa, Lab
A5: 2 | B5: 02 Apr 2026 | C5: TMC112215 | E5: GP, Gynecology
A6: 3 | B6: 02 Apr 2026 | C6: TMC129700 | D6: Waqas | E6: Neurology, Dermatology
A7: 4 | B7: 02 Apr 2026 | C7: TMC013889 | D7: Muhammad Ashraf | E7: Physio
A8: 5 | B8: 04 Apr 2026 | C8: TMC127629 | D8: Monir | E8: ENT
A9: 6 | B9: 05 Apr 2026 | C9: TMC129901 | D9: Wasim Khan | E9: Dr Mofeed, Dr Said, Radiology
A10: 7 | B10: 05 Apr 2026 | C10: TMC128369 | D10: Shafi | E10: Physio
A11: 8 | B11: 06 Apr 2026 | C11: TMC129966 | D11: Rajeesh Kalluvettu | E11: Dr Asma, Dr Hala, Lab, USG
A12: 9 | B12: 06 Apr 2026 | C12: TMC125736 | D12: Hiba | E12: Gynecology
A13: 10 | B13: 07 Apr 2026 | C13: TMC129901 | D13: Wasim | E13: GP
A14: 11 | B14: 07 Apr 2026 | C14: TMC013889 | D14: Muhammad Ashraf | E14: Physio
A15: 12 | B15: 08 Apr 2026 | C15: TMC130066 | D15: Birendra Thapa | E15: Dr Afsheen, Dr Agnel, Radiology
A16: 13 | B16: 08 Apr 2026 | C16: TMC130067 | D16: Zeeshan Muhammad | E16: Dr Afsheen, Dr Agnel, Lab
A17: 14 | B17: 08 Apr 2026 | C17: TMC130070 | D17: Amina Mubeen | E17: Dr Higazy, Dr Night, Radiology, Injection
... A19: 16 | B19: 08 Apr 2026 | C19: TMC125736 | D19: Hiba | E19: Gynecology Follow-up
A20: 17 | B20: 09 Apr 2026 | C20: TMC126338 | E20: GP
A21: 18 | B21: 09 Apr 2026 | C21: TMC015474 | E21: Cardiology, ECG
A22: 19 | B22: 09 Apr 2026 | C22: TMC129901 | D22: Wasim | E22: GP Follow-up
A23: 20 | B23: 09 Apr 2026 | C23: TMC035577 | D23: Shiva Kumar | E23: Physio
A24: 21 | B24: 10 Apr 2026 | C24: TMC130070 | D24: Amina Mubeen | E24: GP
A25: 22 | B25: 10 Apr 2026 | C25: TMC013889 | D25: Muhammad Ashraf | E25: Physio
A26: 23 | B26: 11 Apr 2026 | C26: TMC129012 | D26: Shakil Khan | E26: Ophthalmology
A27: 24 | B27: 11 Apr 2026 | C27: TMC130067 | D27: Zeeshan | E27: Orthopedic
A28: 25 | B28: 11 Apr 2026 | C28: TMC035577 | D28: Shiva Kumar | E28: Physio
A29: 26 | B29: 12 Apr 2026 | C29: TMC130232 | D29: Mohammed Hanif | E29: Dr Roaa, Dr Nandi, Radiology
A30: 27 | B30: 12 Apr 2026 | C30: TMC130253 | D30: Waleed Muhammad | E30: Dr Mustafa, Dr Nandi, ENT Services
A31: 28 | B31: 13 Apr 2026 | C31: TMC130314 | D31: Jabair Shaik | E31: Dr Mustafa, Dr Nandi, Dr Alaa, Lab, ENT Services
A32: 29 | B32: 13 Apr 2026 | C32: TMC130070 | D32: Amina Mubeen | E32: Family Medicine
A33: 30 | B33: 13 Apr 2026 | C33: TMC128925 | D33: Azizullah | E33: GP, Dermatology
... A59: 56 | B59: 24 Apr 2026 | C59: TMC129130 | D59: Ibrahim | E59: GP
A60: 57 | B60: 25 Apr 2026 | C60: TMC054178 | E60: Gynecology, Lab
A61: 58 | B61: 25 Apr 2026 | C61: TMC130067 | D61: Zeeshan | E61: Orthopedic
A62: 59 | B62: 26 Apr 2026 | C62: TMC054178 | E62: MRI
A63: 60 | B63: 26 Apr 2026 | C63: TMC130808 | D63: Muhammed Naeem | E63: GP, Lab
A64: 61 | B64: 28 Apr 2026 | C64: TMC130607 | D64: Sutiarti | E64: Dental, Gastroenterology
A65: 62 | B65: 28 Apr 2026 | C65: TMC130067 | D65: Zeeshan | E65: Orthopedic
A66: 63 | B66: 29 Apr 2026 | C66: TMC13066 | D66: Thapa | E66: Orthopedic
...

Sheet May-2026
A1: NAME : MUHAMMED FAIZ
A2: PATIENT DATA OF MAY 2026
A3: Sl No | B3: Date | C3: File Number | D3: Patient Name | E3: Consultation / Service / Department | F3: Bill Amount
A4: 1 | B4: 02 May 2026 | C4: TMC130067 | D4: Zeeshan | E4: Orthopedic
A5: 2 | B5: 03 May 2026 | C5: TMC112215 | E5: ENT, X-Ray, ENT Services
A6: 3 | B6: 03 May 2026 | C6: TMC013889 | D6: Muhammad Ashraf | E6: GP, Orthopedic, Family Medicine, Physio
A7: 4 | B7: 03 May 2026 | C7: TMC125736 | D7: Hiba | E7: Gynecology
A8: 5 | B8: 04 May 2026 | C8: TMC112215 | E8: Endocrinology
A9: 6 | B9: 04 May 2026 | C9: TMC128585 | D9: Usman Ali | E9: GP, Lab, X-Ray
A10: 7 | B10: 05 May 2026 | C10: TMC130607 | D10: Sutiarti | E10: Dental
A11: 8 | B11: 05 May 2026 | C11: TMC130253 | D11: Waleed | E11: GP, Orthopedic, Family Medicine
A12: 9 | B12: 05 May 2026 | C12: TMC128214 | D12: Shamma | E12: Family Medicine, Lab
A13: 10 | B13: 08 May 2026 | C13: TMC013889 | D13: Muhammad Ashraf | E13: Physio
A14: 11 | B14: 08 May 2026 | C14: TMC128214 | D14: Shamma | E14: Family Medicine Follow-up
A15: 12 | B15: 09 May 2026 | C15: TMC054178 | E15: Gynecology Follow-up
A16: 13 | B16: 09 May 2026 | C16: TMC127629 | D16: Monir | E16: GP, Orthopedic, Pulmonology, Neurology, Lab, X-Ray
A17: 14 | B17: 10 May 2026 | C17: TMC127629 | D17: Monir | E17: ENT
A18: 15 | B18: 11 May 2026 | C18: TMC131766 | D18: Gafoor Hussain
A19: 16 | B19: 11 May 2026 | C19: TMC131768 | D19: Zaheer Abbas
A20: 17 | B20: 11 May 2026 | C20: TMC131814 | D20: Shifanath
A21: 18 | B21: 11 May 2026 | C21: TMC131813 | D21: Abbas
A22: 19 | B22: 11 May 2026 | C22: TMC129012 | D22: Shakil Khan | E22: Ophthalmology
A23: 20 | B23: 11 May 2026 | C23: TMC128369 | D23: Shafi | E23: Physio
A24: 21 | B24: 12 May 2026 | C24: TMC130607 | D24: Sutiarti | E24: Dental
A25: 22 | B25: 12 May 2026 | C25: TMC128214 | D25: Shamma | E25: Family Medicine
A26: 23 | B26: 13 May 2026 | C26: TMC131973 | D26: Azeem Khan
A27: 24 | B27: 13 May 2026 | C27: TMC131962 | D27: Shahzad
A28: 25 | B28: 13 May 2026 | C28: TMC131963 | D28: Waqas
A29: 26 | B29: 13 May 2026 | C29: TMC013889 | D29: Muhammad Ashraf | E29: Family Medicine Follow-up, Physio
A30: 27 | B30: 15 May 2026 | C30: TMC128214 | D30: Shamma | E30: Family Medicine
A31: 28 | B31: 16 May 2026 | C31: TMC132099 | D31: Shibin
A32: 29 | B32: 16 May 2026 | C32: TMC132091 | D32: Bushra Bilal | E32: Dr Mirey, USG
A33: 30 | B33: 16 May 2026 | C33: TMC127629 | D33: Monir | E33: Pulmonology
A34: 31 | B34: 17 May 2026 | C34: TMC131768 | D34: Zaheer Abbas
A35: 32 | B35: 17 May 2026 | C35: TMC128369 | D35: Shafi | E35: Physio
A36: 33 | B36: 18 May 2026 | C36: TMC131766 | D36: Gafoor Hussain
A37: 34 | B37: 18 May 2026 | C37: TMC131768 | D37: Zaheer Abbas
A38: 35 | B38: 19 May 2026 | C38: TMC131814 | D38: Shifanath
A39: 36 | B39: 20 May 2026 | C39: TMC127390 | D39: Dancel Gen | E39: GP, ENT
A40: 37 | B40: 21 May 2026 | C40: TMC100262 | D40: Salim
...

Sheet Jun-2026
A1: NAME : MUHAMMED FAIZ
A2: PATIENT DATA OF JUNE 2026
A3: Sl No | B3: Date | C3: File Number | D3: Patient Name | E3: Consultation / Service / Department | F3: Bill Amount
A4: 1 | B4: 01 Jun 2026 | C4: TMC126953 | D4: Muhammed Seemab | E4: Pediatric
A5: 2 | B5: 01 Jun 2026 | C5: TMC132800 | D5: Ayesha | E5: Dermatology, Dr Agnel
A6: 3 | B6: 01 Jun 2026 | C6: TMC129012 | D6: Shakil Khan | E6: Ophthalmology
A7: 4 | B7: 01 Jun 2026 | C7: TMC126952 | D7: Fathima Seemab | E7: Pediatric
A8: 5 | B8: 02 Jun 2026 | C8: TMC132848 | D8: Thamaraselvam | E8: GP, Dr Bassim, Dr Higazy, Radiology, Ophthalmology Services, Plaster
A9: 6 | B9: 02 Jun 2026 | C9: TMC013889 | D9: Muhammad Ashraf | E9: Physio
A10: 7 | B10: 03 Jun 2026 | C10: TMC112215 | E10: ENT Follow-up, Injection
A11: 8 | B11: 04 Jun 2026 | C11: TMC132800 | D11: Ayesha | E11: Orthopedic Follow-up, Internal Medicine, Lab
A12: 9 | B12: 04 Jun 2026 | C12: TMC130070 | D12: Amina Mubeen | E12: Gynecology Follow-up
A13: 10 | B13: 04 Jun 2026 | C13: TMC127534 | D13: Nasreldin | E13: GP, Orthopedic
A14: 11 | B14: 04 Jun 2026 | C14: TMC126952 | D14: Fathima Seemab | E14: Pediatric Follow-up
A15: 12 | B15: 04 Jun 2026 | C15: TMC126953 | D15: Muhammed Seemab | E15: Pediatric Follow-up
A16: 13 | B16: 05 Jun 2026 | C16: TMC013889 | D16: Muhammad Ashraf | E16: Physio
A17: 14 | B17: 07 Jun 2026 | C17: TMC132800 | D17: Ayesha | E17: Internal Medicine Follow-up
A18: 15 | B18: 07 Jun 2026 | C18: TMC133105 | D18: Raja Naseer
A19: 16 | B19: 07 Jun 2026 | C19: TMC127534 | D19: Nasreldin | E19: Orthopedic Follow-up, Lab, X-Ray
A20: 17 | B20: 08 Jun 2026 | C20: TMC112824 | D20: Arslan Khalid | E20: GP, ENT, CT
A21: 18 | B21: 08 Jun 2026 | C21: TMC133118 | D21: Kowsalya Saravana | E21: GP, ENT, Lab
A22: 19 | B22: 10 Jun 2026 | C22: TMC132800 | D22: Ayesha | E22: Internal Medicine Follow-up
A23: 20 | B23: 10 Jun 2026 | C23: TMC129268 | D23: Shirin Saleem | E23: Dr Asma, Dr Ibthihaj, USG
A24: 21 | B24: 10 Jun 2026 | C24: TMC127534 | D24: Nasreldin | E24: Orthopedic Follow-up
A25: 22 | B25: 10 Jun 2026 | C25: TMC133207 | D25: Jnat Ullah | E25: GP, Orthopedic, X-Ray
A26: 23 | B26: 13 Jun 2026 | C26: TMC133314 | D26: Jasir Iqbal | E26: GP, ENT, Lab
A27: 24 | B27: 14 Jun 2026 | C27: TMC013889 | D27: Muhammad Ashraf | E27: Physio
A28: 25 | B28: 14 Jun 2026 | C28: TMC089226 | D28: Amina | E28: GP, Lab
A29: 26 | B29: 16 Jun 2026 | C29: TMC132800 | D29: Ayesha | E29: Internal Medicine Follow-up
A30: 27 | B30: 17 Jun 2026 | C30: TMC112824 | D30: Arslan Khalid | E30: GP, ENT
... A53: 50 | B53: 26 Jun 2026 | C53: TMC130067 | D53: Zeeshan | E53: GP
A54: 51 | B54: 27 Jun 2026 | C54: TMC133960 | D54: Muhammed
A55: 52 | B55: 27 Jun 2026 | C55: TMC130067 | D55: Zeeshan | E55: Neurology
A56: 53 | B56: 30 Jun 2026 | C56: TMC128369 | D56: Shafi | E56: Physio
A58: TOTAL PATIENTS OF JUNE 2026 | E58: =COUNTA(B4:B56)
A59: TOTAL BILL AMOUNT OF JUNE 2026 | F59: =SUM(F4:F56)

Sheet Jul-2026
A1: NAME : MUHAMMED FAIZ
A2: PATIENT DATA OF JULY 2026
A3: Sl No | B3: Date | C3: File Number | D3: Patient Name | E3: Consultation / Service / Department | F3: Bill Amount
A25: TOTAL PATIENTS OF JULY 2026 | E25: =COUNTA(B4:B23)
A26: TOTAL BILL AMOUNT OF JULY 2026 | F26: =SUM(F4:F23)

Sheet Aug-2026
A1: NAME : MUHAMMED FAIZ
A2: PATIENT DATA OF AUGUST 2026
A3: Sl No | B3: Date | C3: File Number | D3: Patient Name | E3: Consultation / Service / Department | F3: Bill Amount
A4: 1 | B4: 01 Aug 2026 | C4: TVIP009213588 | D4: Tawoor Khan | E4: GP, Orthopedic
A5: 2 | B5: 01 Aug 2026 | C5: TVIP01017126 | D5: Jeganathan Perumal | E5: Urology
A6: 3 | B6: 01 Aug 2026 | C6: TVIP01017200 | D6: Nuha Bint Mohammed Ameer | E6: Pediatric, Orthopedic
A7: 4 | B7: 01 Aug 2026 | C7: TVIP01017202 | D7: Huda Bint Mohammed Ameer | E7: Pediatric
A8: 5 | B8: 01 Aug 2026 | C8: TVIP01017204 | D8: Wafa Bint Mohammed Ameer | E8: Pediatric
A9: 6 | B9: 01 Aug 2026 | C9: TVIP01017333 | D9: Abdul Basith Manalodi | E9: Orthopedic, Dr Jonel
A10: 7 | B10: 01 Aug 2026 | C10: TVIP01017403 | D10: Deepak Sahadevan Sumangala | E10: GP, ENT, Neurology
A11: 8 | B11: 01 Aug 2026 | C11: TVIP01017438 | D11: Sakkeer Babu Chemmala | E11: GP
A12: 9 | B12: 01 Aug 2026 | C12: TVIP01017441 | D12: Mohamed Ali Thazhathody | E12: GP
A13: 10 | B13: 01 Aug 2026 | C13: TVIP01017443 | D13: Mohammed Rafeekh Thottungal | E13: GP, Family Medicine
A14: 11 | B14: 01 Aug 2026 | C14: TVIP01017455 | D14: Mohamed Afsal Vettan Shahul Hameed | E14: GP
A15: 12 | B15: 01 Aug 2026 | C15: TVIP01017456 | D15: Sidheek Ayappally Saidhalavi | E15: GP
... A56: 53 | B56: 15 Aug 2026 | C56: TVIP01019048 | D56: Asmaa Waled Farhan | E56: GP
A57: 54 | B57: 15 Aug 2026 | C57: TVIP01019069 | D57: Muhammad Salman
A58: 55 | B58: 15 Aug 2026 | C58: TVIP01019067 | D58: Thajul Islam
A59: 56 | B59: 15 Aug 2026 | C59: TMC125740 | D59: Muhammed Ameen
A60: 57 | B60: 16 Aug 2026 | C60: +971 58 109 0012 | D60: Mohammed Salih | E60: Pediatric
A61: 58 | B61: 16 Aug 2026 | C61: TVIP00979556 | D61: Zayan Hamad Maheen | E61: Pediatric, General
A62: 59 | B62: 16 Aug 2026 | C62: TVIP01019248 | D62: Najiya Suhaira | E62: GP, ENT
A63: 60 | B63: 17 Aug 2026 | C63: TVIP00902268 | D63: Muhammed | E63: Urology
A64: 61 | B64: 17 Aug 2026 | C64: TVIP01019048 | D64: Asmaa Waled Farhan | E64: Endocrinology, GP
A65: 62 | B65: 17 Aug 2026 | C65: TVIP01019307 | D65: Sahin Nisam Mozhiyottil Ibrahim | E65: Family Medicine
A66: 63 | B66: 17 Aug 2026 | C66: 554755770
A67: 64 | B67: 18 Aug 2026 | C67: TVIP00830448 | D67: Kavitha Satheesh
A68: 65 | B68: 19 Aug 2026 | C68: TVIP01019637 | D68: Shintu Eappen Thenalil | E68: GP, ENT, Family Medicine
A69: 66 | B69: 20 Aug 2026 | C69: TVIP01017627 | D69: Krishna Priya
A70: 67 | B70: 20 Aug 2026 | C70: TVIP00830448 | D70: Kavitha Satheesh | E70: Gynecology, Endocrinology, Physio
A71: 68 | B71: 20 Aug 2026 | C71: TVIP00902268 | D71: Muhammed | E71: Urology
A72: 69 | B72: 20 Aug 2026 | C72: TVIP00918146 | D72: Muhammed Emin | E72: Lab
A73: 70 | B73: 20 Aug 2026 | C73: TVIP00973129 | D73: Hiba Kunnummal | E73: Gynecology
A74: 71 | B74: 20 Aug 2026 | C74: +971 55 767 9323 | D74: Seifuddeen | E74: Internal Medicine
A75: 72 | B75: 20 Aug 2026 | C75: TVIP00654762 | D75: Shahzad Afsar | E75: ENT
A76: 73 | B76: 21 Aug 2026 | C76: TVIP00830448 | D76: Kavitha Satheesh | E76: MRI - WC, Physio
A77: 74 | B77: 23 Aug 2026 | C77: TVIP00830448 | D77: Kavitha Satheesh | E77: Gynecology, Physio
A78: 75 | B78: 23 Aug 2026 | C78: TVIP01017627 | D78: Krishna Priya | E78: Dermatology
A79: 76 | B79: 23 Aug 2026 | C79: TVIP01019935 | D79: Prakash | E79: GP, Internal Medicine
A80: 77 | B80: 23 Aug 2026 | C80: +971 52 759 1340 | D80: Shameen | E80: ENT
...

Sheet Sep-2026
A1: NAME : MUHAMMED FAIZ
A2: PATIENT DATA OF SEPTEMBER 2026
A3: Sl No | B3: Date | C3: File Number | D3: Patient Name | E3: Consultation / Service / Department | F3: Bill Amount
A4: 1 | B4: 01 Sep 2026 | C4: TVIP00946055 | D4: Hessa Musallem Hamad | E4: Dermatology
A5: 2 | B5: 02 Sep 2026 | C5: TVIP00950460 | D5: Mustafa Hassan Refaieh | E5: Rafeh
A6: 3 | B6: 02 Sep 2026 | C6: TVIP01020920 | D6: Zaid Mustafa Refaieh | E6: Ahmed Yousif Ali
A7: 4 | B7: 02 Sep 2026 | C7: TVIP01021338 | D7: Kayan Ashour Hany | E7: Pediatric
A8: 5 | B8: 03 Sep 2026 | C8: TVIP01015196 | D8: Adel Fares Afifi Ibrahim Afifi | E8: Internal Medicine
A9: 6 | B9: 05 Sep 2026 | C9: TVIP00604064 | D9: Sabil Ullah Hajat Khan | E9: Internal Medicine
A10: 7 | B10: 05 Sep 2026 | C10: TVIP00979556 | D10: Zayan Hamad Maheen | E10: Pediatric
A11: 8 | B11: 05 Sep 2026 | C11: TVIP00950460 | D11: Mustafa Hassan Refaieh | E11: Rafeh
A12: 9 | B12: 05 Sep 2026 | C12: TVIP01021611 | D12: Gulapchan Rajbanshi | E12: GP, Ophthalmology
A13: 10 | B13: 09 Sep 2026 | C13: TVIP01015196 | D13: Adel Fares Afifi Ibrahim Afifi | E13: GP
A14: 11 | B14: 11 Sep 2026 | C14: TVIP00830448 | D14: Kavitha Satheesh | E14: Physio
A15: 12 | B15: 11 Sep 2026 | C15: 784-1991-1902026-3 | D15: Rengin Thomas | E15: Family Medicine
... A18: 15 | B18: 13 Sep 2026 | C18: TVIP01017206 | D18: Rana Muhammad Zubair | E18: Physio
A19: 16 | B19: 13 Sep 2026 | C19: 543653363 | D19: Khalid
A20: 17 | B20: 13 Sep 2026 | C20: TVIP00950460 | D20: Mustafa Hassan Refaieh | E20: Rafeh
A21: 18 | B21: 13 Sep 2026 | C21: TVIP01020917 | D21: Shahid Mustafa Refaieh | E21: Pediatric
A22: 19 | B22: 14 Sep 2026 | C22: TVIP01017202 | D22: Huda Bint Mohammed Ameer | E22: Pediatric
A23: 20 | B23: 14 Sep 2026 | C23: TVIP01017200 | D23: Nuha Bint Mohammed Ameer | E23: Pediatric
A24: 21 | B24: 15 Sep 2026 | C24: TVIP01017206 | D24: Rana Muhammad Zubair | E24: Physio
A25: 22 | B25: 16 Sep 2026 | C25: TVIP01017333 | D25: Abdul Basith Manalodi | E25: Physio
A26: 23 | B26: 17 Sep 2026 | C26: TVIP01001897 | D26: Mohammed Ameer Puzhangaraillath | E26: Family Medicine, Internal Medicine
A27: 24 | B27: 17 Sep 2026 | C27: TVIP01017200 | D27: Nuha Bint Mohammed Ameer | E27: Pediatric
A28: 25 | B28: 17 Sep 2026 | C28: TVIP01017204 | D28: Wafa Bint Mohammed Ameer | E28: Pediatric
A29: 26 | B29: 17 Sep 2026 | C29: 784-2022-8214492-6 | D29: Mariam Thomas | E29: Pediatric
A30: 27 | B30: 17 Sep 2026 | C30: TVIP01017202 | D30: Huda Bint Mohammed Ameer | E30: Pediatric
A31: 28 | B31: 18 Sep 2026 | C31: TVIP00830448 | D31: Kavitha Satheesh | E31: Physio
... A43: 40 | B43: 30 Sep 2026 | C43: TVIP00950460 | D43: Mustafa Hassan Refaieh | E43: ENT
A45: TOTAL PATIENTS OF SEPTEMBER 2026 | E45: =COUNTA(B4:B43)
A46: TOTAL BILL AMOUNT OF SEPTEMBER 2026 | F46: =SUM(F4:F43)

Sheet Oct-2026
A1: NAME : MUHAMMED FAIZ
A2: PATIENT DATA OF OCTOBER 2026
A3: Sl No | B3: Date | C3: File Number | D3: Patient Name | E3: Consultation / Service / Department | F3: Bill Amount
A4: 1 | B4: Oct 2026 | C4: TVIP00951311 | D4: Rajulama | E4: GP, Internal Medicine
A5: 2 | B5: Oct 2026 | C5: TVIP00970507 | D5: Muhammad Nadeem | E5: GP, Orthopedic
A6: 3 | B6: Oct 2026 | C6: TVIP00832371 | D6: Bahaa Ahmeda | E6: GP, Pulmonology
A7: 4 | B7: Oct 2026 | C7: TVIP00638836 | D7: Md Monerul | E7: GP, ENT
A8: 5 | B8: Oct 2026 | C8: TVIP00832371 | D8: Bahaa Ahmeda | E8: GP, Orthopedic
A9: 6 | B9: Oct 2026 | C9: TVIP01025552 | D9: Waheed Ahmad | E9: GP, ENT
A10: 7 | B10: Oct 2026 | C10: TVIP00889712 | D10: Jaseer Noor | E10: GP, ENT
A11: 8 | B11: Oct 2026 | C11: TVIP00805474 | D11: Alizay Muhammad | E11: GP, ENT, Dermatology
A12: 9 | B12: Oct 2026 | C12: TVIP00654682 | D12: Faisal Muhamed | E12: GP, ENT
A13: 10 | B13: Oct 2026 | C13: TVIP01007079 | D13: Akhil Valayanattu | E13: GP, ENT
A14: 11 | B14: Oct 2026 | C14: TVIP01026288 | D14: Muhammad Tahir | E14: GP, Orthopedic
A15: 12 | B15: Oct 2026 | C15: TVIP01025552 | D15: Waheed Ahmad | E15: GP, ENT
... A25: 22 | B25: Oct 2026 | C25: TVIP00973129 | D25: Hiba Kunnummal | E25: Gynecology
A27: TOTAL PATIENTS OF OCTOBER 2026 | E27: =COUNTA(B4:B25)
A28: TOTAL BILL AMOUNT OF OCTOBER 2026 | F28: =SUM(F4:F25)
